#VRML_SIM R2022a utf8
WorldInfo {
  coordinateSystem "NUE"
}
Viewpoint {
  orientation -0.08190646427940979 -0.16424373235638162 -0.9830133913080183 1.6047856189439451
  position 0.021552349227466044 2.6972921001573544 -0.7780786344031783
}
TexturedBackground {
}
TexturedBackgroundLight {
}
RectangleArena {
  rotation -0.5773502691896258 0.5773502691896258 0.5773502691896258 2.0943951023931957
  floorSize 0.254 1.524
  floorTileSize 0.508 0.508
}
DEF epuck E-puck {
  hidden position_0_0 -2.870611534477318e-08
  hidden position_0_1 -5.7901925285065594e-08
  hidden rotation_1 0 -1 0 2.9802322387695313e-08
  hidden rotation_2 0 -0.9999999999999999 0 5.960464477539063e-08
  translation 0.6100079675428545 -8.870612885454598e-05 0.008010378001512754
  rotation 0.0005780227972595459 0.7074906146579086 0.7067225028684319 3.1404178862760483
  controller "lab3_task1"
  supervisor TRUE
  camera_width 50
  turretSlot [
    InertialUnit {
      rotation 0 1 0 0
    }
    DEF righthinge HingeJoint {
      jointParameters HingeJointParameters {
        position 2.5303821812972806e-07
        axis -1 0 0
        anchor 0 0.025 0
      }
      device [
        RotationalMotor {
          name "right wheel motor"
          consumptionFactor 70
          controlPID 8 2 0.5
        }
        PositionSensor {
          name "right wheel sensor"
        }
      ]
      endPoint Solid {
        translation 0.04500995778380096 0.025013380752640695 -2.4671933237912768e-05
        rotation 0.9999993203501398 0.0010052732343720006 -0.0005905294087673308 4.636836869016623
        children [
          DEF WHEEL Transform {
            translation -0.007 0.01 -0.05
            rotation 0 0 1 1.57
            children [
              Shape {
                appearance PBRAppearance {
                  baseColor 0 0 0
                  transparency 1
                  roughness 1
                  metalness 0
                }
                geometry Cylinder {
                  height 0.01
                  radius 0.02
                }
              }
            ]
            rotationStep 0.25
          }
        ]
        name "right wheel(1)"
        boundingObject USE WHEEL
        physics DEF PHYSICS_WHEEL Physics {
          density -1
          mass 0.05
        }
        rotationStep 0.25
      }
    }
    DEF lefthinge HingeJoint {
      jointParameters HingeJointParameters {
        position -6.082626669012825e-08
        axis -1 0 0
        anchor 0 0.025 0
      }
      device [
        RotationalMotor {
          name "left wheel motor"
          consumptionFactor 70
          controlPID 8 0 0
        }
        PositionSensor {
          name "left wheel sensor"
        }
      ]
      endPoint Solid {
        translation -0.04501012942703836 0.024977671980060893 -4.5733977520165206e-05
        rotation -0.9999982113393647 0.00047275276191902934 -0.001831344559912412 1.2425809594628
        children [
          DEF WHEEL Transform {
            translation 0.007 0 -0.05
            rotation 0 0 1 1.57
            children [
              Shape {
                appearance PBRAppearance {
                  baseColor 0.1 0.1 0.1
                  transparency 1
                  roughness 1
                  metalness 0
                }
                geometry Cylinder {
                  height 0.01
                  radius 0.02
                }
              }
            ]
            rotationStep 0.25
          }
        ]
        name "left wheel(1)"
        boundingObject USE WHEEL
        physics DEF PHYSICS_WHEEL Physics {
          density -1
          mass 0.05
        }
      }
    }
    DEF front_ds DistanceSensor {
      translation 0.045 0 -0.01
      rotation 0 1 0 0
      name "front_ds"
      recognitionColors [
        0 0 0
      ]
      lookupTable [
        0 0 0
        1.27 1.27 0
      ]
    }
    DEF right_ds DistanceSensor {
      translation 0.01 -0.035 -0.01
      rotation 0 0 1 -1.57
      name "right_ds"
      lookupTable [
        0 0 0
        1.27 1.27 0
      ]
    }
    DEF left_ds DistanceSensor {
      translation 0.01 0.035 -0.01
      rotation 0 0 1 1.57
      name "left_ds"
      lookupTable [
        0 0 0
        1.27 1.27 0
      ]
    }
    Camera {
      translation 0 -0.01 -0.045
      name "camera1"
      recognitionColors [
        1 1 0
      ]
      fieldOfView 1.57
      width 80
      height 80
      recognition Recognition {
      }
    }
  ]
}
